// European Union Public License version 1.2
// Copyright Â© 2023 Rick Beerendonk

package org.exceptions._catch

fun main() {
    try {
        val result = 10 / 0
        println(result)  // Not executed
    } catch (e: ArithmeticException) {
        println("Error: ${e.message}")  // Error: / by zero
    }
}
